Workbook

Sheet Danh_sách_gia_vị
A1: Tính giá cost
A2: Tên gia vị | B2: Đơn vị tính | C2: Đơn giá | D2: Trọng lượng cho mỗi đơn vị (G) | E2: Giá cho 1g | G2: Công thức cho seasoning ngũ vị | H2: Trọng lượng (G) | I2: Giá cost | J2: Cost của 1g hoàn chỉnh | K2: Cost cho 10g gia vị | L2: Cost cho 15g gia vị
A3: Muối hồng | B3: Hủ | C3: 110000 | D3: 1000 | E3: =SUM(C3/D3) -> 110 | G3: Muối hồng | H3: 30 | I3: =H3*E3 -> 3300
A4: Bột nêm rau củ | B4: Bịch | C4: 200000 | D4: 1000 | E4: =SUM(C4/D4) -> 200 | G4: Bột nêm rau củ | H4: 20 | I4: =H4*E4 -> 4000
A5: Ngũ vị hương | B5: Hủ | C5: 31000 | D5: 40 | E5: =SUM(C5/D5) -> 775 | G5: Ngũ vị hương | H5: 10 | I5: =H5*E5 -> 7750
A6: Bộ̣t tỏi | B6: Hủ | C6: 34000 | D6: 70 | E6: =SUM(C6/D6) -> 485.71429 | G6: Bộ̣t tỏi | H6: 15 | I6: =H6*E6 -> 7285.7143
A7: Bột hành | B7: Hủ | C7: 45000 | D7: 70 | E7: =SUM(C7/D7) -> 642.85714 | G7: Bột hành | H7: 10 | I7: =H7*E7 -> 6428.5714
A8: Bột sả | B8: Hủ | C8: 26000 | D8: 40 | E8: =SUM(C8/D8) -> 650 | G8: Tiêu đen xay | H8: 5 | I8: =H8*E16 -> 750
A9: Bột ớt | B9: Hủ | C9: 24000 | D9: 45 | E9: =SUM(C9/D9) -> 533.33333 | G9: Bột nghệ | H9: 3 | I9: =H9*E13 -> 2314.2857
A10: Bột ngò | B10: Hủ | C10: 25000 | D10: 40 | E10: =SUM(C10/D10) -> 625 | G10: Đường mía | H10: 12 | I10: =H10*E15 -> 924
A11: Bột thì là | B11: Hủ | C11: 44000 | D11: 40 | E11: =C11/D11 -> 1100 | G11: Tổng cộng | H11: =SUM(H3:H10) -> 105 | I11: =SUM(I3:I10) -> 32752.571 | J11: =I11/H11 -> 311.92925 | K11: =J11*10 -> 3119.2925 | L11: =J11*15 -> 4678.9388
A12: Bột quế | B12: Hủ | C12: 24000 | D12: 35 | E12: =SUM(C12/D12) -> 685.71429
A13: Bột nghệ | B13: Hủ | C13: 27000 | D13: 35 | E13: =SUM(C13/D13) -> 771.42857 | G13: Công thức cho chanh sả | H13: Trọng lượng (G) | I13: Giá cost | J13: Cost của 1g hoàn chỉnh | K13: Cost cho 10g gia vị /1kg thịt | L13: Cost cho 15g gia vị /1kg thịt
A14: Bột gừng | B14: Hủ | C14: 32000 | D14: 40 | E14: =SUM(C14/D14) -> 800 | G14: Muối hồng | H14: 45 | I14: =H14*E3 -> 4950
A15: Đường mía | B15: Bịch | C15: 77000 | D15: 1000 | E15: =SUM(C15/D15) -> 77 | G15: Đường mía | H15: 20 | I15: =H15*E15 -> 1540
A16: Tiêu đen | B16: Hủ | C16: 150000 | D16: 1000 | E16: =SUM(C16/D16) -> 150 | G16: Sả bột | H16: 15 | I16: =H16*E8 -> 9750
A17: Mắc khén | B17: Hủ | C17: 43000 | D17: 20 | E17: =SUM(C17/D17) -> 2150 | G17: Bột hành | H17: 15 | I17: =H17*E7 -> 9642.8571
A18: Lá mùi tây | B18: Hủ | C18: 30000 | D18: 20 | E18: =SUM(C18/D18) -> 1500 | G18: Tiêu đen xay | H18: 10 | I18: =H18*E16 -> 1500
A19: Lá́ xạ hương | B19: Hủ | C19: 33000 | D19: 25 | E19: =SUM(C19/D19) -> 1320 | G19: Bột lá chanh | H19: 10 | I19: =H19*E24 -> 5200
A20: Lá húng quế basil | B20: Hủ | C20: 33000 | D20: 20 | E20: =SUM(C20/D20) -> 1650 | G20: Tổng cộng | H20: =SUM(H14:H19) -> 115 | I20: =SUM(I14:I19) -> 32582.857 | J20: =I20/H20 -> 283.32919 | K20: =J20*10 -> 2833.2919 | L20: =J20*15 -> 4249.9379
A21: Lá hương thảo (rosemary | B21: Hủ | C21: 33000 | D21: 25 | E21: =SUM(C21/D21) -> 1320
A22: Kinh giới tây oregano | B22: Bịch | C22: 30000 | D22: 10 | E22: =SUM(C22/D22) -> 3000 | G22: Công thức cho sả nghệ | H22: Trọng lượng (G) | I22: Giá cost | J22: Cost của 1g hoàn chỉnh | K22: Cost cho 10g gia vị /1kg thịt | L22: Cost cho 15g gia vị /1kg thịt
A23: Hạt dổi | B23: Bịch | C23: 60000 | D23: 50 | E23: =SUM(C23/D23) -> 1200 | G23: Bột tỏi | H23: 15 | I23: =SUM(H23*E6) -> 7285.7143
A24: Bột lá chanh | B24: Bịch | C24: 26000 | D24: 50 | E24: =SUM(C24/D24) -> 520 | G24: Bột cà ri | H24: 5 | I24: =H24*E27 -> 3000
A25: Hạt mè | B25: Bịch | C25: 100000 | D25: 1000 | E25: =SUM(C25/D25) -> 100 | G25: Tiêu đen xay | H25: 5 | I25: =H25*E16 -> 750
A26: Dầu điều | G26: Bột nghệ | H26: 10 | I26: =H26*E13 -> 7714.2857
A27: Bột cari | B27: Bịch | C27: 6000 | D27: 10 | E27: =SUM(C27/D27) -> 600 | G27: Bột nêm rau củ | H27: 15 | I27: =H27*E4 -> 3000
G28: Muối hồng | H28: 26 | I28: =H28*E3 -> 2860
G29: Bột sả | H29: 13 | I29: =H29*E8 -> 8450
G30: Bột ớt | H30: 7 | I30: =H30*E9 -> 3733.3333
G31: Tổng cộng | H31: =SUM(H23:H30) -> 96 | I31: =SUM(I23:I30) -> 36793.333 | J31: =I31/H31 -> 383.26389 | K31: =J31*10 -> 3832.6389 | L31: =J31*15 -> 5748.9583
G33: Công thức cho Tây bắc | H33: Trọng lượng (G) | I33: Giá cost | J33: Cost của 1g hoàn chỉnh | K33: Cost cho 10g gia vị /1kg thịt | L33: Cost cho 15g gia vị /1kg thịt
G34: Muối hồng | H34: 27 | I34: =H34*E3 -> 2970
G35: Tiêu đen xay | H35: 5 | I35: =H35*E16 -> 750
G36: Bột tỏi | H36: 15 | I36: =H36*E6 -> 7285.7143
G37: Bột nêm rau củ | H37: 27 | I37: =H37*E4 -> 5400
G38: Bột lá chanh | H38: 8 | I38: =H38*E24 -> 4160
G39: Dổi | H39: 8 | I39: =H39*E23 -> 9600
G40: Mắc khén | H40: 7 | I40: =H40*E17 -> 15050
G41: Bột sả | H41: 10 | I41: =H41*E8 -> 6500
...

Sheet Tính_giá_vốn_món_chính
A1: Tính giá cost | K1: Gà cajun 1KG/10bich 100g | L1: Đơn vị tính | M1: Số lượng | N1: Giá cost | O1: Cost của 100g hoàn chỉnh | P1: Giá sỉ lãi 30% | Q1: Thuế | R1: Giá bán lãi 40% | S1: Thuế
A2: Tên gia vị | B2: Đơn vị tính | C2: Đơn giá | D2: Trọng lượng cho mỗi đơn vị (G) | E2: Giá cho 1g | K2: Ức gà | L2: G | M2: 1000 | N2: 70000
A3: Túi hút chân không | B3: Cái | C3: 60000 | D3: 100 | E3: =SUM(C3/D3) -> 600 | K3: gia vị cajun | L3: G | M3: 15 | N3: =M3*'Danh_sách_gia_vị'!J55 -> 7227.9602
A4: Dầu ăn hướng dương | B4: Chai/Lít | C4: 85000 | D4: 1000 | E4: =SUM(C4/D4) -> 85 | K4: Tỏi băm + trang trí | L4: G | M4: 20 | N4: =M4*E17 -> 1000
A5: Bao tay | B5: Cái | C5: 92000 | D5: 100 | E5: =SUM(C5/D5) -> 920 | K5: Giấy | L5: tờ | M5: 6 | N5: =M5*E6 -> 1020
A6: Khăn giấy bếp 2 lớp | B6: Tờ | C6: 34000 | D6: 200 | E6: =SUM(C6/D6) -> 170 | K6: Bao tay | L6: Cái | M6: 2 | N6: =M6*E5 -> 1840
A7: Thăn heo (nạc) | B7: KG | C7: 111000 | D7: 694 | E7: =SUM(C7/D7) -> 159.94236 | K7: Túi hút | L7: Cái | M7: 10 | N7: =M7*E3 -> 6000
A8: Cốt lết | B8: KG | C8: 105000 | D8: 1000 | E8: =SUM(C8/D8) -> 105 | K8: Dầu | L8: G | M8: 20 | N8: =M8*E4 -> 1700
A9: Nạt vai | B9: KG | C9: 110000 | D9: 1000 | E9: =SUM(C9/D9) -> 110 | K9: Phát sinh phụ | L9: KG | M9: 1000 | N9: =M9*E20 -> 50000
A10: Tôm thẻ | B10: KG | C10: 360000 | D10: 1000 | E10: =SUM(C10/D10) -> 360 | K10: Tem nhãn | L10: Cái | M10: 10 | N10: =M10*E21 -> 7300
A11: Cá thu nguyên lát | B11: KG | C11: 190000 | D11: 1000 | E11: =SUM(C11/D11) -> 190 | K11: Túi giữ nhiệt | L11: Gói | M11: 10 | N11: =M11*E22 -> 18000
A12: Ức gà bình điền | B12: KG | C12: 65000 | D12: 1000 | E12: =SUM(C12/D12) -> 65 | K12: Tổng cộng | N12: =SUM(N2:N11) -> 164087.96 | O12: =N12/10 -> 16408.796 | P12: =O12*1.3 -> 21331.435 | Q12: =P12*1.045 -> 22291.349 | R12: =P12*1.3 -> 27730.865 | S12: =R12*1.045 -> 28978.754
A13: Đù̀i bòi gà | B13: KG | C13: 68000 | D13: 1000 | E13: =SUM(C13/D13) -> 68 | K13: Gà ngũ vị 1KG/10bich 100g | L13: Đơn vị tính | M13: Số lượng | N13: Giá cost | O13: Cost của 100g hoàn chỉnh | P13: Giá sỉ lãi 30% | Q13: Thuế | R13: Giá bán lãi 40% | S13: Thuế
A14: Thịt bò thăn | B14: KG | C14: 295000 | D14: 1000 | E14: =SUM(C14/D14) -> 295 | K14: Ức gà | L14: G | M14: 1000 | N14: 70000
A15: Đùi bò | B15: KG | C15: 260000 | D15: 1000 | E15: =SUM(C15/D15) -> 260 | K15: gia vị ngũ vị | L15: G | M15: 15 | N15: =M15*'Danh_sách_gia_vị'!J11 -> 4678.9388
A16: Cá chẻm phi lê | B16: KG | C16: 190000 | D16: 1000 | E16: =SUM(C16/D16) -> 190 | K16: Tỏi băm + trang trí | L16: G | M16: 20 | N16: =M16*E17 -> 1000
A17: Tỏi và trang trí | B17: KG | C17: 50000 | D17: 1000 | E17: =SUM(C17/D17) -> 50 | K17: Giấy | L17: tờ | M17: 6 | N17: =M17*E6 -> 1020
A18: Cá hồi | B18: KG | C18: 380000 | D18: 1000 | E18: =SUM(C18/D18) -> 380 | K18: Bao tay | L18: Cái | M18: 2 | N18: =M18*E5 -> 1840
A19: Cá tầm | B19: KG | C19: 200000 | D19: 1000 | E19: =SUM(C19/D19) -> 200 | K19: Túi hút | L19: Cái | M19: 10 | N19: =M19*E3 -> 6000
A20: Phát sinh phụ (công, dụng cụ) | B20: KG | C20: 50000 | D20: 1000 | E20: =SUM(C20/D20) -> 50 | K20: Dầu | L20: G | M20: 20 | N20: =M20*E4 -> 1700
A21: Tem nhãn | B21: Cái | C21: =340000+25000 -> 365000 | D21: 500 | E21: =SUM(C21/D21) -> 730 | K21: Phát sinh phụ | L21: KG | M21: 1000 | N21: =M21*E20 -> 50000
A22: Túi giữ nhiệt | B22: Gói | C22: 9000 | D22: 5 | E22: =SUM(C22/D22) -> 1800 | K22: Tem nhãn | L22: Cái | M22: 10 | N22: =M22*E21 -> 7300
K23: Túi giữ nhiệt | L23: Gói | M23: 10 | N23: =M23*E22 -> 18000
K24: Tổng cộng | N24: =SUM(N14:N23) -> 161538.94 | O24: =N24/10 -> 16153.894 | P24: =O24*1.3 -> 21000.062 | Q24: =P24*1.045 -> 21945.065 | R24: =P24*1.3 -> 27300.081 | S24: =R24*1.045 -> 28528.584
A25: Thăn bò ngũ vị 1KG/10bich 100g | B25: Đơn vị tính | C25: Số lượng | D25: Giá cost | E25: Cost của 100g hoàn chỉnh | F25: Giá sỉ lãi 30% | G25: Thuế | H25: Giá bán lãi 30% | I25: Thuế | K25: Gà gừng tỏi 1KG/10bich 100g | L25: Đơn vị tính | M25: Số lượng | N25: Giá cost | O25: Cost của 100g hoàn chỉnh | P25: Giá sỉ lãi 30% | Q25: Thuế | R25: Giá bán lãi 40% | S25: Thuế
A26: Thăn bò | B26: G | C26: 1000 | D26: =C26*E14 -> 295000 | K26: Ức gà | L26: G | M26: 1000 | N26: =M26*E12 -> 65000
A27: gia vị ngũ vị | B27: G | C27: 15 | D27: =C27*'Danh_sách_gia_vị'!J43 -> 7544.0867 | K27: gia vị gừng tỏi | L27: G | M27: 15 | N27: =M27*'Danh_sách_gia_vị'!J74 -> 4383.381
A28: Tỏi băm + trang trí | B28: G | C28: 20 | D28: =C28*E17 -> 1000 | K28: Tỏi băm + trang trí | L28: G | M28: 20 | N28: =M28*E17 -> 1000
A29: Giấy | B29: tờ | C29: 6 | D29: =C29*E6 -> 1020 | K29: Giấy | L29: tờ | M29: 6 | N29: =M29*E6 -> 1020
A30: Bao tay | B30: Cái | C30: 2 | D30: =C30*E5 -> 1840 | K30: Bao tay | L30: Cái | M30: 2 | N30: =M30*E5 -> 1840
A31: Túi hút | B31: Cái | C31: 10 | D31: =C31*E3 -> 6000 | K31: Túi hút | L31: Cái | M31: 10 | N31: =M31*E3 -> 6000
A32: Dầu | B32: G | C32: 20 | D32: =C32*E4 -> 1700 | K32: Dầu | L32: G | M32: 20 | N32: =M32*E4 -> 1700
A33: Phát sinh phụ | B33: KG | C33: 1000 | D33: =C33*E20 -> 50000 | K33: Phát sinh phụ | L33: KG | M33: 1000 | N33: =M33*E20 -> 50000
A34: Tem nhãn | B34: Cái | C34: 10 | D34: =C34*E21 -> 7300 | K34: Tem nhãn | L34: Cái | M34: 10 | N34: =M34*E21 -> 7300
A35: Túi giữ nhiệt | B35: Gói | C35: 10 | D35: =C35*E22 -> 18000 | K35: Túi giữ nhiệt | L35: Gói | M35: 10 | N35: =M35*E22 -> 18000
A36: Tổng cộng | D36: =SUM(D26:D35) -> 389404.09 | E36: =D36/10 -> 38940.409 | F36: =E36*1.3 -> 50622.531 | G36: =F36*1.015 -> 51381.869 | H36: =F36*1.3 -> 65809.291 | I36: =H36*1.015 -> 66796.43 | K36: Tổng cộng | N36: =SUM(N26:N35) -> 156243.38 | O36: =N36/10 -> 15624.338 | P36: =O36*1.3 -> 20311.64 | Q36: =P36*1.045 -> 21225.663 | R36: =P36*1.3 -> 26405.131 | S36: =R36*1.045 -> 27593.362
A37: Thăn bò tây bắc 1KG/10bich 100g | B37: Đơn vị tính | C37: Số lượng | D37: Giá cost | E37: Cost của 100g hoàn chỉnh | F37: Giá sỉ lãi 30% | G37: Thuế | H37: Giá bán lãi 30% | I37: Thuế | K37: Ức gà sả chanh 1KG/10bich 100g | L37: Đơn vị tính | M37: Số lượng | N37: Giá cost | O37: Cost của 100g hoàn chỉnh | P37: Giá sỉ lãi 30% | Q37: Thuế | R37: Giá bán lãi 40% | S37: Thuế
A38: Thăn bò | B38: G | C38: 1000 | D38: =C38*E14 -> 295000 | K38: Ức gà | L38: G | M38: 1000 | N38: =M38*E12 -> 65000
A39: gia vị tây bắc | B39: G | C39: 15 | D39: =C39*'Danh_sách_gia_vị'!J43 -> 7544.0867 | K39: gia vị sả chanh | L39: G | M39: 15 | N39: =M39*'Danh_sách_gia_vị'!J20 -> 4249.9379
A40: Tỏi băm + trang trí | B40: G | C40: 20 | D40: =C40*E17 -> 1000 | K40: Tỏi băm + trang trí | L40: G | M40: 20 | N40: =M40*E17 -> 1000
...

Sheet Nhân_viên
A1: Tên Nhân Viên (KHÔNG ĐƯỢC TRÙNG) | B1: SĐT | C1: Địa chỉ | D1: Ghi chú
A2: Hằng | F2: Thông tin Nhân Viên không cho phép trùng
A3: Uyên
A4: Thảo
A5: Hằng
A6: Hà
A7: Khách page

Sheet Hướng dẫn
A1: MEALFIT - Quy trình mới
A2: 1 | B2: Nhập khách mới ở sheet Khach_hang. (ví dụ Anh Quân hay Chị Nga theo từng hàng)
A3: 2 | B3: Tạo đơn mới ở sheet Don_hang: chỉ cần nhập Ngày, Tên KH, Đã thanh toán, Trạng thái đơn, Ghi chú (những cái khác nhập tiếp ở Sheet sau).
A4: 3 | B4: Thêm các món của đơn hàng ở sheet Chi_tiet_don_hang: nhập Mã đơn có ghi ở chỗ Sheet Don_Hang, Món, Trọng lượng, Số lượng.
A5: 4 | B5: Tổng SL, Tổng tiền, Còn lại và Trạng thái thanh toán sẽ tự tính ở sheet Don_hang.
A6: 5 | B6: Các sheet CŨ* là dữ liệu cũ để tham chiếu, không cần nhập thêm vào đó.
A7: Lưu ý | B7: Các sheet mới dùng tên không dấu để tránh lỗi parse khi mở bằng Google Sheets.
A8: HƯỚNG DẪN THÊM MÓN | B8: 1. Khi thêm món mới, tạo món trong sheet Tính_giá_vốn_món_chính, ghi nhớ giá vốn hoàn chỉnh cho 100g, 2. Cập nhật món vào menu trong sheet Thuc_don, nhập cột tô vàng: Cột A: Tên món Cột B: Giá bán 100g Cột E: Giá bán 150g Cột H: Giá bán 200g 3. Ở cột C, nối công thức đến ô giá vốn 100g của món mới trong sheet Tinh_gia_von_mon_chinh. Ví dụ: "=Tinh_gia_von_mon_chinh!O97" 4. Copy công thức từ dòng món phía trên xuống các cột tô xám: Cột D: Lợi nhuận 100g Cột F: Giá vốn 150g Cột G: Lợi nhuận 150g Cột I: Giá vốn 200g Cột J: Lợi nhuận 200g 5. Cập nhật vào sheet Bang_gia, mỗi món là tương ứng với 3 dòng trong bảng (100g, 150g, 200g). Có 3 cột D, E, F sẽ chạy theo giá từ trong sheet Thuc_don => Quy trình là cập nhật vào Tính_giá_vốn_món_chính -> Thuc_don -> Bang_gia
A9: TÍNH NĂNG COMBO | B9: 1. Quản lý combo ở sheet Combo_master và Combo_chi_tiet. 2. Nhập/tạo combo ở Combo_master: tên combo, giá bán combo. Giá vốn combo sẽ tự cộng từ Combo_chi_tiet nếu có chi tiết. 3. Ở Combo_chi_tiet, mỗi dòng là 1 món thành phần trong combo (ví dụ Combo giữ dáng = Ức gà cajun 100g + Tôm gừng tỏi 100g + Nạc heo tây bắc 150g). 4. Khi tạo đơn ở Chi_tiet_don_hang, nhập Món = tên combo và Trọng lượng = Combo. Giá combo sẽ tự lấy từ Bang_gia / Combo_master. 5. Cột Q ở Chi_tiet_don_hang và cột F trên BILL sẽ tự hiện "Gồm: ..." để biết combo có những món gì.
A10: SOẠN HÀNG / ĐI CHỢ | B10: 1. Dùng sheet Tong_hop_soan_hang. 2. Nhập Từ ngày / Đến ngày ở B2 và D2. 3. Sheet chỉ tổng hợp các đơn trong khoảng ngày và (chưa giao HOẶC chưa thanh toán). 4. Nếu đơn có combo, hệ thống sẽ tự bung combo thành các món con để soạn hàng. 5. Bảng bên trái: tổng số gói cần soạn theo món / trọng lượng. 6. Bảng bên phải: tổng gram cần đi chợ theo hàng chính (ứng với sheet Map_di_cho).

Sheet Thuc_don
A1: Món | B1: 100g | C1: Giá vốn | D1: Lợi nhuận | E1: Tỷ lệ lãi | F1: 150g | G1: Giá vốn | H1: Lợi nhuận | I1: Tỷ lệ lãi | J1: 200g | K1: Giá vốn | L1: Lợi nhuận | M1: Tỷ lệ lãi
A2: Ức gà cajun | B2: 25000 | C2: ='Tính_giá_vốn_món_chính'!O12 -> 16408.796 | D2: =B2-C2 -> 8591.204 | E2: =D2/B2*100 -> 34.364816 | F2: 36000 | G2: =C2*1.5 -> 24613.194 | H2: =F2-G2 -> 11386.806 | I2: =H2/F2*100 -> 31.630017 | J2: 48000 | K2: =C2*2 -> 32817.592 | L2: =J2-K2 -> 15182.408 | M2: =L2/J2*100 -> 31.630017
A3: Ức gà ngũ vị | B3: 25000 | C3: ='Tính_giá_vốn_món_chính'!O24 -> 16153.894 | D3: =B3-C3 -> 8846.1061 | E3: =D3/B3*100 -> 35.384424 | F3: 36000 | G3: =C3*1.5 -> 24230.841 | H3: =F3-G3 -> 11769.159 | I3: =H3/F3*100 -> 32.692109 | J3: 48000 | K3: =C3*2 -> 32307.788 | L3: =J3-K3 -> 15692.212 | M3: =L3/J3*100 -> 32.692109
A4: Ức gà sả chanh | B4: 25000 | C4: ='Tính_giá_vốn_món_chính'!O48 -> 15610.994 | D4: =B4-C4 -> 9389.0062 | E4: =D4/B4*100 -> 37.556025 | F4: 36000 | G4: =C4*1.5 -> 23416.491 | H4: =F4-G4 -> 12583.509 | I4: =H4/F4*100 -> 34.954193 | J4: 48000 | K4: =C4*2 -> 31221.988 | L4: =J4-K4 -> 16778.012 | M4: =L4/J4*100 -> 34.954193
A5: Ứ́c gà gừng tỏi | B5: 25000 | C5: ='Tính_giá_vốn_món_chính'!O36 -> 15624.338 | D5: =B5-C5 -> 9375.6619 | E5: =D5/B5*100 -> 37.502648 | F5: 36000 | G5: =C5*1.5 -> 23436.507 | H5: =F5-G5 -> 12563.493 | I5: =H5/F5*100 -> 34.898591 | J5: 48000 | K5: =C5*2 -> 31248.676 | L5: =J5-K5 -> 16751.324 | M5: =L5/J5*100 -> 34.898591
A6: Ức gà̀ cà ri | B6: 25000 | C6: ='Tính_giá_vốn_món_chính'!O60 -> 15519.551 | D6: =B6-C6 -> 9480.449 | E6: =D6/B6*100 -> 37.921796 | F6: 36000 | G6: =C6*1.5 -> 23279.327 | H6: =F6-G6 -> 12720.673 | I6: =H6/F6*100 -> 35.335204 | J6: 48000 | K6: =C6*2 -> 31039.102 | L6: =J6-K6 -> 16960.898 | M6: =L6/J6*100 -> 35.335204
A7: Ức gà tiêu chanh | B7: 25000 | C7: ='Tính_giá_vốn_món_chính'!O136 -> 15526.766 | D7: =B7-C7 -> 9473.234 | E7: =D7/B7*100 -> 37.892936 | F7: 36000 | G7: =C7*1.5 -> 23290.149 | H7: =F7-G7 -> 12709.851 | I7: =H7/F7*100 -> 35.305142 | J7: 48000 | K7: =C7*2 -> 31053.532 | L7: =J7-K7 -> 16946.468 | M7: =L7/J7*100 -> 35.305142
A8: Cốt lết mè rang | B8: 30000 | C8: ='Tính_giá_vốn_món_chính'!O73 -> 19700.079 | D8: =B8-C8 -> 10299.921 | E8: =D8/B8*100 -> 34.33307 | F8: 44000 | G8: =C8*1.5 -> 29550.119 | H8: =F8-G8 -> 14449.881 | I8: =H8/F8*100 -> 32.840639 | J8: 58000 | K8: =C8*2 -> 39400.158 | L8: =J8-K8 -> 18599.842 | M8: =L8/J8*100 -> 32.068693
A9: Cốt lết gừng tỏi | B9: 30000 | C9: ='Tính_giá_vốn_món_chính'!O85 -> 19624.338 | D9: =B9-C9 -> 10375.662 | E9: =D9/B9*100 -> 34.58554 | F9: 44000 | G9: =C9*1.5 -> 29436.507 | H9: =F9-G9 -> 14563.493 | I9: =H9/F9*100 -> 33.098847 | J9: 58000 | K9: =C9*2 -> 39248.676 | L9: =J9-K9 -> 18751.324 | M9: =L9/J9*100 -> 32.329869
A10: Cốt lết ngũ vị | B10: 30000 | C10: ='Tính_giá_vốn_món_chính'!O85 -> 19624.338 | D10: =B10-C10 -> 10375.662 | E10: =D10/B10*100 -> 34.58554 | F10: 44000 | G10: =C10*1.5 -> 29436.507 | H10: =F10-G10 -> 14563.493 | I10: =H10/F10*100 -> 33.098847 | J10: 58000 | K10: =C10*2 -> 39248.676 | L10: =J10-K10 -> 18751.324 | M10: =L10/J10*100 -> 32.329869
A11: Nạ̣c heo tây bắc | B11: 30000 | C11: ='Tính_giá_vốn_món_chính'!O122 -> 20440.409 | D11: =B11-C11 -> 9559.5913 | E11: =D11/B11*100 -> 31.865304 | F11: 44000 | G11: =C11*1.5 -> 30660.613 | H11: =F11-G11 -> 13339.387 | I11: =H11/F11*100 -> 30.316789 | J11: 58000 | K11: =C11*2 -> 40880.817 | L11: =J11-K11 -> 17119.183 | M11: =L11/J11*100 -> 29.515832
A12: Nạc heo sả nghệ | B12: 30000 | C12: ='Tính_giá_vốn_món_chính'!O97 -> 18460.896 | D12: =B12-C12 -> 11539.104 | E12: =D12/B12*100 -> 38.463681 | F12: 44000 | G12: =C12*1.5 -> 27691.344 | H12: =F12-G12 -> 16308.656 | I12: =H12/F12*100 -> 37.065128 | J12: 58000 | K12: =C12*2 -> 36921.792 | L12: =J12-K12 -> 21078.208 | M12: =L12/J12*100 -> 36.341739
A13: Nạ̣c heo ngũ vị | B13: 30000 | C13: ='Tính_giá_vốn_món_chính'!O109 -> 20153.894 | D13: =B13-C13 -> 9846.1061 | E13: =D13/B13*100 -> 32.820354 | F13: 44000 | G13: =C13*1.5 -> 30230.841 | H13: =F13-G13 -> 13769.159 | I13: =H13/F13*100 -> 31.293544 | J13: 58000 | K13: =C13*2 -> 40307.788 | L13: =J13-K13 -> 17692.212 | M13: =L13/J13*100 -> 30.503814
A14: Thăn bò ngũ vị | B14: 59000 | C14: ='Tính_giá_vốn_món_chính'!E36 -> 38940.409 | D14: =B14-C14 -> 20059.591 | E14: =D14/B14*100 -> 33.999307 | F14: 87000 | G14: =C14*1.5 -> 58410.613 | H14: =F14-G14 -> 28589.387 | I14: =H14/F14*100 -> 32.861364 | J14: =116000 -> 116000 | K14: =C14*2 -> 77880.817 | L14: =J14-K14 -> 38119.183 | M14: =L14/J14*100 -> 32.861364
A15: Thăn bò tây bắc | B15: 59000 | C15: ='Tính_giá_vốn_món_chính'!E48 -> 38940.409 | D15: =B15-C15 -> 20059.591 | E15: =D15/B15*100 -> 33.999307 | F15: 87000 | G15: =C15*1.5 -> 58410.613 | H15: =F15-G15 -> 28589.387 | I15: =H15/F15*100 -> 32.861364 | J15: =116000 -> 116000 | K15: =C15*2 -> 77880.817 | L15: =J15-K15 -> 38119.183 | M15: =L15/J15*100 -> 32.861364
A16: Thăn bò̀ cajun | B16: 59000 | C16: ='Tính_giá_vốn_món_chính'!E60 -> 38908.796 | D16: =B16-C16 -> 20091.204 | E16: =D16/B16*100 -> 34.052888 | F16: 87000 | G16: =C16*1.5 -> 58363.194 | H16: =F16-G16 -> 28636.806 | I16: =H16/F16*100 -> 32.915869 | J16: 116000 | K16: =C16*2 -> 77817.592 | L16: =J16-K16 -> 38182.408 | M16: =L16/J16*100 -> 32.915869
A17: Tôm gừng tỏi | B17: 59000 | C17: ='Tính_giá_vốn_món_chính'!E73 -> 45192.338 | D17: =B17-C17 -> 13807.662 | E17: =D17/B17*100 -> 23.402817 | F17: 86000 | G17: =C17*1.5 -> 67788.507 | H17: =F17-G17 -> 18211.493 | I17: =H17/F17*100 -> 21.176154 | J17: 115000 | K17: =C17*2 -> 90384.676 | L17: =J17-K17 -> 24615.324 | M17: =L17/J17*100 -> 21.404629
A18: Tôm cajun | B18: 59000 | C18: ='Tính_giá_vốn_món_chính'!E85 -> 45476.796 | D18: =B18-C18 -> 13523.204 | E18: =D18/B18*100 -> 22.920685 | F18: 86000 | G18: =C18*1.5 -> 68215.194 | H18: =F18-G18 -> 17784.806 | I18: =H18/F18*100 -> 20.680007 | J18: 115000 | K18: =C18*2 -> 90953.592 | L18: =J18-K18 -> 24046.408 | M18: =L18/J18*100 -> 20.90992
A19: Tôm kiểu Ý | B19: 59000 | C19: ='Tính_giá_vốn_món_chính'!E85 -> 45476.796 | D19: =B19-C19 -> 13523.204 | E19: =D19/B19*100 -> 22.920685 | F19: 86000 | G19: =C19*1.5 -> 68215.194 | H19: =F19-G19 -> 17784.806 | I19: =H19/F19*100 -> 20.680007 | J19: 115000 | K19: =C19*2 -> 90953.592 | L19: =J19-K19 -> 24046.408 | M19: =L19/J19*100 -> 20.90992
A20: Tôm tiêu chanh | B20: 59000 | C20: ='Tính_giá_vốn_món_chính'!E97 -> 45094.766 | D20: =B20-C20 -> 13905.234 | E20: =D20/B20*100 -> 23.568193 | F20: 86000 | G20: =C20*1.5 -> 67642.149 | H20: =F20-G20 -> 18357.851 | I20: =H20/F20*100 -> 21.346338 | J20: 115000 | K20: =C20*2 -> 90189.532 | L20: =J20-K20 -> 24810.468 | M20: =L20/J20*100 -> 21.57432
A21: Cá thu cà ri | B21: 47000 | C21: ='Tính_giá_vốn_món_chính'!E110 -> 28476.796 | D21: =B21-C21 -> 18523.204 | E21: =D21/B21*100 -> 39.411072 | F21: 69000 | G21: =C21*1.5 -> 42715.194 | H21: =F21-G21 -> 26284.806 | I21: =H21/F21*100 -> 38.093922 | J21: 92000 | K21: =C21*2 -> 56953.592 | L21: =J21-K21 -> 35046.408 | M21: =L21/J21*100 -> 38.093922
A22: Cá thu kiểu Âu | B22: 47000 | C22: ='Tính_giá_vốn_món_chính'!E175 -> 28521.594 | D22: =B22-C22 -> 18478.406 | E22: =D22/B22*100 -> 39.315758 | F22: 69000 | G22: =C22*1.5 -> 42782.391 | H22: =F22-G22 -> 26217.609 | I22: =H22/F22*100 -> 37.996535 | J22: 92000 | K22: =C22*2 -> 57043.187 | L22: =J22-K22 -> 34956.813 | M22: =L22/J22*100 -> 37.996535
A23: Cá hồi cajun | B23: 63000 | C23: ='Tính_giá_vốn_món_chính'!E123 -> 47406.796 | D23: =B23-C23 -> 15593.204 | E23: =D23/B23*100 -> 24.751117 | F23: 93000 | G23: =C23*1.5 -> 71110.194 | H23: =F23-G23 -> 21889.806 | I23: =H23/F23*100 -> 23.537426 | J23: 124000 | K23: =C23*2 -> 94813.592 | L23: =J23-K23 -> 29186.408 | M23: =L23/J23*100 -> 23.537426
A24: Cá hồi kiểu âu | B24: 63000 | C24: ='Tính_giá_vốn_món_chính'!E136 -> 47591.594 | D24: =B24-C24 -> 15408.406 | E24: =D24/B24*100 -> 24.457788 | F24: 93000 | G24: =C24*1.5 -> 71387.391 | H24: =F24-G24 -> 21612.609 | I24: =H24/F24*100 -> 23.239365 | J24: 124000 | K24: =C24*2 -> 95183.187 | L24: =J24-K24 -> 28816.813 | M24: =L24/J24*100 -> 23.239365
A25: Cá tầm kiểu Ý | B25: 49000 | C25: ='Tính_giá_vốn_món_chính'!E149 -> 29565.302 | D25: =B25-C25 -> 19434.698 | E25: =D25/B25*100 -> 39.662648 | F25: 73000 | G25: =C25*1.5 -> 44347.954 | H25: =F25-G25 -> 28652.046 | I25: =H25/F25*100 -> 39.249379 | J25: 97000 | K25: =C25*2 -> 59130.605 | L25: =J25-K25 -> 37869.395 | M25: =L25/J25*100 -> 39.040613
A26: Cá tầm gừng tỏi | B26: 49000 | C26: ='Tính_giá_vốn_món_chính'!E162 -> 29192.338 | D26: =B26-C26 -> 19807.662 | E26: =D26/B26*100 -> 40.4238 | F26: 73000 | G26: =C26*1.5 -> 43788.507 | H26: =F26-G26 -> 29211.493 | I26: =H26/F26*100 -> 40.015744 | J26: 97000 | K26: =C26*2 -> 58384.676 | L26: =J26-K26 -> 38615.324 | M26: =L26/J26*100 -> 39.809612
A27: =Combo_tong_hop!B3 -> Combo giữ dáng | B27: =Combo_tong_hop!D3 -> 219000 | C27: =Combo_tong_hop!C3 -> 166038.13 | D27: =IF(OR(B27="",C27=""),"",B27-C27) -> 52961.871 | E27: =IF(OR(B27="",D27=""),"",D27/B27*100) -> 24.183503
A28: =Combo_tong_hop!B4 -> Combo giảm cân | B28: =Combo_tong_hop!D4 -> 345000 | C28: =Combo_tong_hop!C4 -> 261026.49 | D28: =IF(OR(B28="",C28=""),"",B28-C28) -> 83973.512 | E28: =IF(OR(B28="",D28=""),"",D28/B28*100) -> 24.340148
A29: =Combo_tong_hop!B5 -> Combo Tăng cơ | B29: =Combo_tong_hop!D5 -> 395000 | C29: =Combo_tong_hop!C5 -> 302062.97 | D29: =IF(OR(B29="",C29=""),"",B29-C29) -> 92937.033 | E29: =IF(OR(B29="",D29=""),"",D29/B29*100) -> 23.528363
A30: =Combo_tong_hop!B6 -> Combo Power Fit | B30: =Combo_tong_hop!D6 -> 536000 | C30: =Combo_tong_hop!C6 -> 408246.73 | D30: =IF(OR(B30="",C30=""),"",B30-C30) -> 127753.27 | E30: =IF(OR(B30="",D30=""),"",D30/B30*100) -> 23.834566
A31: =Combo_tong_hop!B7 -> Combo giữ dáng. | B31: 219000 | C31: =C5+C7+C8+C21+C15+C18 -> 163745.18 | D31: =IF(OR(B31="",C31=""),"",B31-C31) -> 55254.816 | E31: =IF(OR(B31="",D31=""),"",D31/B31*100) -> 25.23051
A32: =Combo_tong_hop!B8 -> Combo giảm cân. | B32: 345000 | C32: =C2+C7+C5+C6+C12+C8+C22+C20+C18+C16 -> 259242.38 | D32: =IF(OR(B32="",C32=""),"",B32-C32) -> 85757.622 | E32: =IF(OR(B32="",D32=""),"",D32/B32*100) -> 24.857282
A33: =Combo_tong_hop!B9 -> Combo Tăng cơ. | B33: 394000 | C33: =G2+G7+G6+G11+G9+G16+G20+G22 -> 300067.52 | D33: =IF(OR(B33="",C33=""),"",B33-C33) -> 93932.477 | E33: =IF(OR(B33="",D33=""),"",D33/B33*100) -> 23.84073
A34: =Combo_tong_hop!B10 -> Combo Power Fit. | B34: 524000 | C34: =K6+K7+K5+K12+K8+K21+K15+K18 -> 395451.26 | D34: =IF(OR(B34="",C34=""),"",B34-C34) -> 128548.74 | E34: =IF(OR(B34="",D34=""),"",D34/B34*100) -> 24.532202
A35: =Combo_tong_hop!B11 | D35: =IF(OR(B35="",C35=""),"",B35-C35) | E35: =IF(OR(B35="",D35=""),"",D35/B35*100)
A36: =Combo_tong_hop!B12 | D36: =IF(OR(B36="",C36=""),"",B36-C36) | E36: =IF(OR(B36="",D36=""),"",D36/B36*100)
A37: =Combo_tong_hop!B13 | D37: =IF(OR(B37="",C37=""),"",B37-C37) | E37: =IF(OR(B37="",D37=""),"",D37/B37*100)
A38: =Combo_tong_hop!B14 | D38: =IF(OR(B38="",C38=""),"",B38-C38) | E38: =IF(OR(B38="",D38=""),"",D38/B38*100)
A39: =Combo_tong_hop!B15 | D39: =IF(OR(B39="",C39=""),"",B39-C39) | E39: =IF(OR(B39="",D39=""),"",D39/B39*100)
A40: =Combo_tong_hop!B16 | D40: =IF(OR(B40="",C40=""),"",B40-C40) | E40: =IF(OR(B40="",D40=""),"",D40/B40*100)
...

Sheet Bang_gia
A1: Key | B1: Món | C1: Trọng lượng | D1: Giá bán | E1: Giá vốn | F1: Lãi/gói
A2: =Bang_gia!B2&" | "&Bang_gia!C2 -> Ức gà cajun | 100g | B2: =Thuc_don!A2 -> Ức gà cajun | C2: 100g | D2: =Thuc_don!B2 -> 25000 | E2: =Thuc_don!C2 -> 16408.796 | F2: =Thuc_don!D2 -> 8591.204
A3: =Bang_gia!B3&" | "&Bang_gia!C3 -> Ức gà cajun | 150g | B3: =Thuc_don!A2 -> Ức gà cajun | C3: 150g | D3: =Thuc_don!F2 -> 36000 | E3: =Thuc_don!G2 -> 24613.194 | F3: =Thuc_don!H2 -> 11386.806
A4: =Bang_gia!B4&" | "&Bang_gia!C4 -> Ức gà cajun | 200g | B4: =Thuc_don!A2 -> Ức gà cajun | C4: 200g | D4: =Thuc_don!J2 -> 48000 | E4: =Thuc_don!K2 -> 32817.592 | F4: =Thuc_don!L2 -> 15182.408
A5: =Bang_gia!B5&" | "&Bang_gia!C5 -> Ức gà ngũ vị | 100g | B5: =Thuc_don!A3 -> Ức gà ngũ vị | C5: 100g | D5: =Thuc_don!B3 -> 25000 | E5: =Thuc_don!C3 -> 16153.894 | F5: =Thuc_don!D3 -> 8846.1061
A6: =Bang_gia!B6&" | "&Bang_gia!C6 -> Ức gà ngũ vị | 150g | B6: =Thuc_don!A3 -> Ức gà ngũ vị | C6: 150g | D6: =Thuc_don!F3 -> 36000 | E6: =Thuc_don!G3 -> 24230.841 | F6: =Thuc_don!H3 -> 11769.159
A7: =Bang_gia!B7&" | "&Bang_gia!C7 -> Ức gà ngũ vị | 200g | B7: =Thuc_don!A3 -> Ức gà ngũ vị | C7: 200g | D7: =Thuc_don!J3 -> 48000 | E7: =Thuc_don!K3 -> 32307.788 | F7: =Thuc_don!L3 -> 15692.212
A8: =Bang_gia!B8&" | "&Bang_gia!C8 -> Ức gà sả chanh | 100g | B8: =Thuc_don!A4 -> Ức gà sả chanh | C8: 100g | D8: =Thuc_don!B4 -> 25000 | E8: =Thuc_don!C4 -> 15610.994 | F8: =Thuc_don!D4 -> 9389.0062
A9: =Bang_gia!B9&" | "&Bang_gia!C9 -> Ức gà sả chanh | 150g | B9: =Thuc_don!A4 -> Ức gà sả chanh | C9: 150g | D9: =Thuc_don!F4 -> 36000 | E9: =Thuc_don!G4 -> 23416.491 | F9: =Thuc_don!H4 -> 12583.509
A10: =Bang_gia!B10&" | "&Bang_gia!C10 -> Ức gà sả chanh | 200g | B10: =Thuc_don!A4 -> Ức gà sả chanh | C10: 200g | D10: =Thuc_don!J4 -> 48000 | E10: =Thuc_don!K4 -> 31221.988 | F10: =Thuc_don!L4 -> 16778.012
A11: =Bang_gia!B11&" | "&Bang_gia!C11 -> Ứ́c gà gừng tỏi | 100g | B11: =Thuc_don!A5 -> Ứ́c gà gừng tỏi | C11: 100g | D11: =Thuc_don!B5 -> 25000 | E11: =Thuc_don!C5 -> 15624.338 | F11: =Thuc_don!D5 -> 9375.6619
A12: =Bang_gia!B12&" | "&Bang_gia!C12 -> Ứ́c gà gừng tỏi | 150g | B12: =Thuc_don!A5 -> Ứ́c gà gừng tỏi | C12: 150g | D12: =Thuc_don!F5 -> 36000 | E12: =Thuc_don!G5 -> 23436.507 | F12: =Thuc_don!H5 -> 12563.493
A13: =Bang_gia!B13&" | "&Bang_gia!C13 -> Ứ́c gà gừng tỏi | 200g | B13: =Thuc_don!A5 -> Ứ́c gà gừng tỏi | C13: 200g | D13: =Thuc_don!J5 -> 48000 | E13: =Thuc_don!K5 -> 31248.676 | F13: =Thuc_don!L5 -> 16751.324
A14: =Bang_gia!B14&" | "&Bang_gia!C14 -> Ức gà̀ cà ri | 100g | B14: =Thuc_don!A6 -> Ức gà̀ cà ri | C14: 100g | D14: =Thuc_don!B6 -> 25000 | E14: =Thuc_don!C6 -> 15519.551 | F14: =Thuc_don!D6 -> 9480.449
A15: =Bang_gia!B15&" | "&Bang_gia!C15 -> Ức gà̀ cà ri | 150g | B15: =Thuc_don!A6 -> Ức gà̀ cà ri | C15: 150g | D15: =Thuc_don!F6 -> 36000 | E15: =Thuc_don!G6 -> 23279.327 | F15: =Thuc_don!H6 -> 12720.673
A16: =Bang_gia!B16&" | "&Bang_gia!C16 -> Ức gà̀ cà ri | 200g | B16: =Thuc_don!A6 -> Ức gà̀ cà ri | C16: 200g | D16: =Thuc_don!$J6 -> 48000 | E16: =Thuc_don!K6 -> 31039.102 | F16: =Thuc_don!L6 -> 16960.898
A17: =Bang_gia!B17&" | "&Bang_gia!C17 -> Ức gà tiêu chanh | 100g | B17: =Thuc_don!A7 -> Ức gà tiêu chanh | C17: 100g | D17: =Thuc_don!$B5 -> 25000 | E17: =Thuc_don!C7 -> 15526.766 | F17: =Thuc_don!D7 -> 9473.234
A18: =Bang_gia!B18&" | "&Bang_gia!C18 -> Ức gà tiêu chanh | 150g | B18: =Thuc_don!A7 -> Ức gà tiêu chanh | C18: 150g | D18: =Thuc_don!$F5 -> 36000 | E18: =Thuc_don!G7 -> 23290.149 | F18: =Thuc_don!H7 -> 12709.851
A19: =Bang_gia!B19&" | "&Bang_gia!C19 -> Ức gà tiêu chanh | 200g | B19: =Thuc_don!A7 -> Ức gà tiêu chanh | C19: 200g | D19: =Thuc_don!$J5 -> 48000 | E19: =Thuc_don!K7 -> 31053.532 | F19: =Thuc_don!L7 -> 16946.468
A20: =Bang_gia!B20&" | "&Bang_gia!C20 -> Cốt lết mè rang | 100g | B20: =Thuc_don!A8 -> Cốt lết mè rang | C20: 100g | D20: =Thuc_don!$B8 -> 30000 | E20: =Thuc_don!$C8 -> 19700.079 | F20: =Thuc_don!$D8 -> 10299.921
A21: =Bang_gia!B21&" | "&Bang_gia!C21 -> Cốt lết mè rang | 150g | B21: =Thuc_don!A8 -> Cốt lết mè rang | C21: 150g | D21: =Thuc_don!F8 -> 44000 | E21: =Thuc_don!G8 -> 29550.119 | F21: =Thuc_don!H8 -> 14449.881
A22: =Bang_gia!B22&" | "&Bang_gia!C22 -> Cốt lết mè rang | 200g | B22: =Thuc_don!A8 -> Cốt lết mè rang | C22: 200g | D22: =Thuc_don!J8 -> 58000 | E22: =Thuc_don!K8 -> 39400.158 | F22: =Thuc_don!L8 -> 18599.842
A23: =Bang_gia!B23&" | "&Bang_gia!C23 -> Cốt lết gừng tỏi | 100g | B23: =Thuc_don!A9 -> Cốt lết gừng tỏi | C23: 100g | D23: =Thuc_don!B9 -> 30000 | E23: =Thuc_don!C9 -> 19624.338 | F23: =Thuc_don!D9 -> 10375.662
A24: =Bang_gia!B24&" | "&Bang_gia!C24 -> Cốt lết gừng tỏi | 150g | B24: =Thuc_don!A9 -> Cốt lết gừng tỏi | C24: 150g | D24: =Thuc_don!F9 -> 44000 | E24: =Thuc_don!G9 -> 29436.507 | F24: =Thuc_don!H9 -> 14563.493
A25: =Bang_gia!B25&" | "&Bang_gia!C25 -> Cốt lết gừng tỏi | 200g | B25: =Thuc_don!A9 -> Cốt lết gừng tỏi | C25: 200g | D25: =Thuc_don!J9 -> 58000 | E25: =Thuc_don!K9 -> 39248.676 | F25: =Thuc_don!L9 -> 18751.324
A26: =Bang_gia!B26&" | "&Bang_gia!C26 -> Cốt lết ngũ vị | 100g | B26: =Thuc_don!A10 -> Cốt lết ngũ vị | C26: 100g | D26: =Thuc_don!B10 -> 30000 | E26: =Thuc_don!C10 -> 19624.338 | F26: =Thuc_don!D10 -> 10375.662
A27: =Bang_gia!B27&" | "&Bang_gia!C27 -> Cốt lết ngũ vị | 150g | B27: =Thuc_don!A10 -> Cốt lết ngũ vị | C27: 150g | D27: =Thuc_don!F10 -> 44000 | E27: =Thuc_don!G10 -> 29436.507 | F27: =Thuc_don!H10 -> 14563.493
A28: =Bang_gia!B28&" | "&Bang_gia!C28 -> Cốt lết ngũ vị | 200g | B28: =Thuc_don!A10 -> Cốt lết ngũ vị | C28: 200g | D28: =Thuc_don!J10 -> 58000 | E28: =Thuc_don!K10 -> 39248.676 | F28: =Thuc_don!L10 -> 18751.324
A29: =Bang_gia!B29&" | "&Bang_gia!C29 -> Nạ̣c heo tây bắc | 100g | B29: =Thuc_don!A11 -> Nạ̣c heo tây bắc | C29: 100g | D29: =Thuc_don!B11 -> 30000 | E29: =Thuc_don!C11 -> 20440.409 | F29: =Thuc_don!D11 -> 9559.5913
A30: =Bang_gia!B30&" | "&Bang_gia!C30 -> Nạ̣c heo tây bắc | 150g | B30: =Thuc_don!A11 -> Nạ̣c heo tây bắc | C30: 150g | D30: =Thuc_don!F11 -> 44000 | E30: =Thuc_don!G11 -> 30660.613 | F30: =Thuc_don!H11 -> 13339.387
A31: =Bang_gia!B31&" | "&Bang_gia!C31 -> Nạ̣c heo tây bắc | 200g | B31: =Thuc_don!A11 -> Nạ̣c heo tây bắc | C31: 200g | D31: =Thuc_don!J11 -> 58000 | E31: =Thuc_don!K11 -> 40880.817 | F31: =Thuc_don!L11 -> 17119.183
A32: =Bang_gia!B32&" | "&Bang_gia!C32 -> Nạc heo sả nghệ | 100g | B32: =Thuc_don!A12 -> Nạc heo sả nghệ | C32: 100g | D32: =Thuc_don!B12 -> 30000 | E32: =Thuc_don!C12 -> 18460.896 | F32: =Thuc_don!D12 -> 11539.104
A33: =Bang_gia!B33&" | "&Bang_gia!C33 -> Nạc heo sả nghệ | 150g | B33: =Thuc_don!A12 -> Nạc heo sả nghệ | C33: 150g | D33: =Thuc_don!F12 -> 44000 | E33: =Thuc_don!G12 -> 27691.344 | F33: =Thuc_don!H12 -> 16308.656
A34: =Bang_gia!B34&" | "&Bang_gia!C34 -> Nạc heo sả nghệ | 200g | B34: =Thuc_don!A12 -> Nạc heo sả nghệ | C34: 200g | D34: =Thuc_don!J12 -> 58000 | E34: =Thuc_don!K12 -> 36921.792 | F34: =Thuc_don!L12 -> 21078.208
A35: =Bang_gia!B35&" | "&Bang_gia!C35 -> Nạ̣c heo ngũ vị | 100g | B35: =Thuc_don!A13 -> Nạ̣c heo ngũ vị | C35: 100g | D35: =Thuc_don!B13 -> 30000 | E35: =Thuc_don!C13 -> 20153.894 | F35: =Thuc_don!D13 -> 9846.1061
A36: =Bang_gia!B36&" | "&Bang_gia!C36 -> Nạ̣c heo ngũ vị | 150g | B36: =Thuc_don!A13 -> Nạ̣c heo ngũ vị | C36: 150g | D36: =Thuc_don!F13 -> 44000 | E36: =Thuc_don!G13 -> 30230.841 | F36: =Thuc_don!H13 -> 13769.159
A37: =Bang_gia!B37&" | "&Bang_gia!C37 -> Nạ̣c heo ngũ vị | 200g | B37: =Thuc_don!A13 -> Nạ̣c heo ngũ vị | C37: 200g | D37: =Thuc_don!J13 -> 58000 | E37: =Thuc_don!K13 -> 40307.788 | F37: =Thuc_don!L13 -> 17692.212
A38: =Bang_gia!B38&" | "&Bang_gia!C38 -> Thăn bò ngũ vị | 100g | B38: =Thuc_don!A14 -> Thăn bò ngũ vị | C38: 100g | D38: =Thuc_don!B14 -> 59000 | E38: =Thuc_don!C14 -> 38940.409 | F38: =Thuc_don!D14 -> 20059.591
A39: =Bang_gia!B39&" | "&Bang_gia!C39 -> Thăn bò ngũ vị | 150g | B39: =Thuc_don!A14 -> Thăn bò ngũ vị | C39: 150g | D39: =Thuc_don!F14 -> 87000 | E39: =Thuc_don!G14 -> 58410.613 | F39: =Thuc_don!H14 -> 28589.387
A40: =Bang_gia!B40&" | "&Bang_gia!C40 -> Thăn bò ngũ vị | 200g | B40: =Thuc_don!A14 -> Thăn bò ngũ vị | C40: 200g | D40: =Thuc_don!J14 -> 116000 | E40: =Thuc_don!K14 -> 77880.817 | F40: =Thuc_don!L14 -> 38119.183
...

Sheet Combo_tong_hop
A1: QUẢN LÝ COMBO
A2: Mã combo | B2: Tên combo | C2: Giá vốn combo | D2: Giá bán combo | E2: Lãi combo | F2: Ghi chú
A3: CB001 | B3: Combo giữ dáng | C3: =IF(A3="","",SUMIFS(Combo_chi_tiet!$H$3:$H$200,Combo_chi_tiet!$A$3:$A$200,$A3)) -> 166038.13 | D3: 219000 | E3: =IF(OR(C3="",D3=""),"",D3-C3) -> 52961.871 | H3: Mã combo không được trùng
A4: CB002 | B4: Combo giảm cân | C4: =IF(A4="","",SUMIFS(Combo_chi_tiet!$H$3:$H$200,Combo_chi_tiet!$A$3:$A$200,$A4)) -> 261026.49 | D4: 345000 | E4: =IF(OR(C4="",D4=""),"",D4-C4) -> 83973.512
A5: CB003 | B5: Combo Tăng cơ | C5: =IF(A5="","",SUMIFS(Combo_chi_tiet!$H$3:$H$200,Combo_chi_tiet!$A$3:$A$200,$A5)) -> 302062.97 | D5: 395000 | E5: =IF(OR(C5="",D5=""),"",D5-C5) -> 92937.033
A6: CB004 | B6: Combo Power Fit | C6: =IF(A6="","",SUMIFS(Combo_chi_tiet!$H$3:$H$200,Combo_chi_tiet!$A$3:$A$200,$A6)) -> 408246.73 | D6: 536000 | E6: =IF(OR(C6="",D6=""),"",D6-C6) -> 127753.27
A7: CB005 | B7: Combo giữ dáng. | C7: =Thuc_don!C31 -> 163745.18 | D7: =Thuc_don!B31 -> 219000 | E7: =IF(OR(C7="",D7=""),"",D7-C7) -> 55254.816
A8: CB006 | B8: Combo giảm cân. | C8: =Thuc_don!C32 -> 259242.38 | D8: =Thuc_don!B32 -> 345000 | E8: =IF(OR(C8="",D8=""),"",D8-C8) -> 85757.622
A9: CB007 | B9: Combo Tăng cơ. | C9: =Thuc_don!C33 -> 300067.52 | D9: =Thuc_don!B33 -> 394000 | E9: =IF(OR(C9="",D9=""),"",D9-C9) -> 93932.477
A10: CB008 | B10: Combo Power Fit. | C10: =Thuc_don!C34 -> 395451.26 | D10: =Thuc_don!B34 -> 524000 | E10: =IF(OR(C10="",D10=""),"",D10-C10) -> 128548.74
A11: CB009 | C11: =Thuc_don!C35 | D11: =Thuc_don!B35 | E11: =IF(OR(C11="",D11=""),"",D11-C11)
A12: CB010 | C12: =Thuc_don!C36 | E12: =IF(OR(C12="",D12=""),"",D12-C12)
A13: CB011 | C13: =Thuc_don!C37 | E13: =IF(OR(C13="",D13=""),"",D13-C13)
A14: CB012 | C14: =Thuc_don!C38 | E14: =IF(OR(C14="",D14=""),"",D14-C14)
A15: CB013 | C15: =Thuc_don!C39 | E15: =IF(OR(C15="",D15=""),"",D15-C15)
A16: CB014 | C16: =Thuc_don!C40 | E16: =IF(OR(C16="",D16=""),"",D16-C16)
A17: CB015 | C17: =Thuc_don!C41 | E17: =IF(OR(C17="",D17=""),"",D17-C17)
A18: CB016 | C18: =Thuc_don!C42 | E18: =IF(OR(C18="",D18=""),"",D18-C18)

Sheet Combo_chi_tiet
A1: CHI TIẾT THÀNH PHẦN COMBO
A2: Mã combo | B2: Tên combo | C2: STT | D2: Tên món | E2: Trọng lượng | F2: SL món/combo | G2: Giá vốn/gói | H2: Tổng giá vốn dòng | I2: Mô tả hiển thị | J2: Key dòng
A3: CB001 | B3: Combo giữ dáng | C3: 1 | D3: Ức gà cajun | E3: 100g | F3: 1 | G3: {=IFERROR(INDEX(Bang_gia!$E$2:$E$1209,MATCH(D3&" | "&E3,Bang_gia!$A$2:$A$1209,0)),"")} -> 16408.796 | H3: =IF(OR(F3="",G3=""),"",F3*G3) -> 16408.796 | I3: =IF(D3="","",D3&" "&E3&IF(F3>1," x"&F3,"")) -> Ức gà cajun 100g | J3: =IF(B3="","",B3&"|"&C3) -> Combo giữ dáng|1
A4: CB001 | B4: Combo giữ dáng | C4: 2 | D4: Ức gà sả chanh | E4: 100g | F4: 1 | G4: {=IFERROR(INDEX(Bang_gia!$E$2:$E$1209,MATCH(D4&" | "&E4,Bang_gia!$A$2:$A$1209,0)),"")} -> 15610.994 | H4: =IF(OR(F4="",G4=""),"",F4*G4) -> 15610.994 | I4: =IF(D4="","",D4&" "&E4&IF(F4>1," x"&F4,"")) -> Ức gà sả chanh 100g | J4: =IF(B4="","",B4&"|"&C4) -> Combo giữ dáng|2
A5: CB001 | B5: Combo giữ dáng | C5: 3 | D5: Nạ̣c heo tây bắc | E5: 100g | F5: 1 | G5: {=IFERROR(INDEX(Bang_gia!$E$2:$E$1209,MATCH(D5&" | "&E5,Bang_gia!$A$2:$A$1209,0)),"")} -> 20440.409 | H5: =IF(OR(F5="",G5=""),"",F5*G5) -> 20440.409 | I5: =IF(D5="","",D5&" "&E5&IF(F5>1," x"&F5,"")) -> Nạ̣c heo tây bắc 100g | J5: =IF(B5="","",B5&"|"&C5) -> Combo giữ dáng|3
A6: CB001 | B6: Combo giữ dáng | C6: 4 | D6: Thăn bò̀ cajun | E6: 100g | F6: 1 | G6: {=IFERROR(INDEX(Bang_gia!$E$2:$E$1209,MATCH(D6&" | "&E6,Bang_gia!$A$2:$A$1209,0)),"")} -> 38908.796 | H6: =IF(OR(F6="",G6=""),"",F6*G6) -> 38908.796 | I6: =IF(D6="","",D6&" "&E6&IF(F6>1," x"&F6,"")) -> Thăn bò̀ cajun 100g | J6: =IF(B6="","",B6&"|"&C6) -> Combo giữ dáng|4
A7: CB001 | B7: Combo giữ dáng | C7: 5 | D7: Tôm kiểu Ý | E7: 100g | F7: 1 | G7: {=IFERROR(INDEX(Bang_gia!$E$2:$E$1209,MATCH(D7&" | "&E7,Bang_gia!$A$2:$A$1209,0)),"")} -> 45476.796 | H7: =IF(OR(F7="",G7=""),"",F7*G7) -> 45476.796 | I7: =IF(D7="","",D7&" "&E7&IF(F7>1," x"&F7,"")) -> Tôm kiểu Ý 100g | J7: =IF(B7="","",B7&"|"&C7) -> Combo giữ dáng|5
A8: CB001 | B8: Combo giữ dáng | C8: 6 | D8: Cá tầm gừng tỏi | E8: 100g | F8: 1 | G8: {=IFERROR(INDEX(Bang_gia!$E$2:$E$1209,MATCH(D8&" | "&E8,Bang_gia!$A$2:$A$1209,0)),"")} -> 29192.338 | H8: =IF(OR(F8="",G8=""),"",F8*G8) -> 29192.338 | I8: =IF(D8="","",D8&" "&E8&IF(F8>1," x"&F8,"")) -> Cá tầm gừng tỏi 100g | J8: =IF(B8="","",B8&"|"&C8) -> Combo giữ dáng|6
A9: CB002 | B9: Combo giảm cân | C9: 1 | D9: Ức gà cajun | E9: 100g | F9: 1 | G9: {=IFERROR(INDEX(Bang_gia!$E$2:$E$1209,MATCH(D9&" | "&E9,Bang_gia!$A$2:$A$1209,0)),"")} -> 16408.796 | H9: =IF(OR(F9="",G9=""),"",F9*G9) -> 16408.796 | I9: =IF(D9="","",D9&" "&E9&IF(F9>1," x"&F9,"")) -> Ức gà cajun 100g | J9: =IF(B9="","",B9&"|"&C9) -> Combo giảm cân|1
A10: CB002 | B10: Combo giảm cân | C10: 2 | D10: Ức gà sả chanh | E10: 100g | F10: 1 | G10: {=IFERROR(INDEX(Bang_gia!$E$2:$E$1209,MATCH(D10&" | "&E10,Bang_gia!$A$2:$A$1209,0)),"")} -> 15610.994 | H10: =IF(OR(F10="",G10=""),"",F10*G10) -> 15610.994 | I10: =IF(D10="","",D10&" "&E10&IF(F10>1," x"&F10,"")) -> Ức gà sả chanh 100g | J10: =IF(B10="","",B10&"|"&C10) -> Combo giảm cân|2
A11: CB002 | B11: Combo giảm cân | C11: 3 | D11: Ứ́c gà gừng tỏi | E11: 100g | F11: 1 | G11: {=IFERROR(INDEX(Bang_gia!$E$2:$E$1209,MATCH(D11&" | "&E11,Bang_gia!$A$2:$A$1209,0)),"")} -> 15624.338 | H11: =IF(OR(F11="",G11=""),"",F11*G11) -> 15624.338 | I11: =IF(D11="","",D11&" "&E11&IF(F11>1," x"&F11,"")) -> Ứ́c gà gừng tỏi 100g | J11: =IF(B11="","",B11&"|"&C11) -> Combo giảm cân|3
A12: CB002 | B12: Combo giảm cân | C12: 4 | D12: Ức gà ngũ vị | E12: 100g | F12: 1 | G12: {=IFERROR(INDEX(Bang_gia!$E$2:$E$1209,MATCH(D12&" | "&E12,Bang_gia!$A$2:$A$1209,0)),"")} -> 16153.894 | H12: =IF(OR(F12="",G12=""),"",F12*G12) -> 16153.894 | I12: =IF(D12="","",D12&" "&E12&IF(F12>1," x"&F12,"")) -> Ức gà ngũ vị 100g | J12: =IF(B12="","",B12&"|"&C12) -> Combo giảm cân|4
A13: CB002 | B13: Combo giảm cân | C13: 5 | D13: Nạc heo sả nghệ | E13: 100g | F13: 1 | G13: {=IFERROR(INDEX(Bang_gia!$E$2:$E$1209,MATCH(D13&" | "&E13,Bang_gia!$A$2:$A$1209,0)),"")} -> 18460.896 | H13: =IF(OR(F13="",G13=""),"",F13*G13) -> 18460.896 | I13: =IF(D13="","",D13&" "&E13&IF(F13>1," x"&F13,"")) -> Nạc heo sả nghệ 100g | J13: =IF(B13="","",B13&"|"&C13) -> Combo giảm cân|5
A14: CB002 | B14: Combo giảm cân | C14: 6 | D14: Cốt lết gừng tỏi | E14: 100g | F14: 1 | G14: {=IFERROR(INDEX(Bang_gia!$E$2:$E$1209,MATCH(D14&" | "&E14,Bang_gia!$A$2:$A$1209,0)),"")} -> 19624.338 | H14: =IF(OR(F14="",G14=""),"",F14*G14) -> 19624.338 | I14: =IF(D14="","",D14&" "&E14&IF(F14>1," x"&F14,"")) -> Cốt lết gừng tỏi 100g | J14: =IF(B14="","",B14&"|"&C14) -> Combo giảm cân|6
... A66: CB008 | B66: Combo Power Fit. | C66: 8 | D66: Tôm cajun | E66: 200g | F66: 1 | G66: {=IFERROR(INDEX(Bang_gia!$E$2:$E$1209,MATCH(D66&" | "&E66,Bang_gia!$A$2:$A$1209,0)),"")} -> 90953.592 | H66: =IF(OR(F66="",G66=""),"",F66*G66) -> 90953.592 | I66: =IF(D66="","",D66&" "&E66&IF(F66>1," x"&F66,"")) -> Tôm cajun 200g | J66: =IF(B66="","",B66&"|"&C66) -> Combo Power Fit.|8
F67: 1 | G67: {=IFERROR(INDEX(Bang_gia!$E$2:$E$1209,MATCH(D67&" | "&E67,Bang_gia!$A$2:$A$1209,0)),"")} | H67: =IF(OR(F67="",G67=""),"",F67*G67) | I67: =IF(D67="","",D67&" "&E67&IF(F67>1," x"&F67,"")) | J67: =IF(B67="","",B67&"|"&C67)
F68: 1 | G68: {=IFERROR(INDEX(Bang_gia!$E$2:$E$1209,MATCH(D68&" | "&E68,Bang_gia!$A$2:$A$1209,0)),"")} | H68: =IF(OR(F68="",G68=""),"",F68*G68) | I68: =IF(D68="","",D68&" "&E68&IF(F68>1," x"&F68,"")) | J68: =IF(B68="","",B68&"|"&C68)
F69: 1 | G69: {=IFERROR(INDEX(Bang_gia!$E$2:$E$1209,MATCH(D69&" | "&E69,Bang_gia!$A$2:$A$1209,0)),"")} | H69: =IF(OR(F69="",G69=""),"",F69*G69) | I69: =IF(D69="","",D69&" "&E69&IF(F69>1," x"&F69,"")) | J69: =IF(B69="","",B69&"|"&C69)
F70: 1 | G70: {=IFERROR(INDEX(Bang_gia!$E$2:$E$1209,MATCH(D70&" | "&E70,Bang_gia!$A$2:$A$1209,0)),"")} | H70: =IF(OR(F70="",G70=""),"",F70*G70) | I70: =IF(D70="","",D70&" "&E70&IF(F70>1," x"&F70,"")) | J70: =IF(B70="","",B70&"|"&C70)
F71: 1 | G71: {=IFERROR(INDEX(Bang_gia!$E$2:$E$1209,MATCH(D71&" | "&E71,Bang_gia!$A$2:$A$1209,0)),"")} | H71: =IF(OR(F71="",G71=""),"",F71*G71) | I71: =IF(D71="","",D71&" "&E71&IF(F71>1," x"&F71,"")) | J71: =IF(B71="","",B71&"|"&C71)
F72: 1 | G72: {=IFERROR(INDEX(Bang_gia!$E$2:$E$1209,MATCH(D72&" | "&E72,Bang_gia!$A$2:$A$1209,0)),"")} | H72: =IF(OR(F72="",G72=""),"",F72*G72) | I72: =IF(D72="","",D72&" "&E72&IF(F72>1," x"&F72,"")) | J72: =IF(B72="","",B72&"|"&C72)
F73: 1 | G73: {=IFERROR(INDEX(Bang_gia!$E$2:$E$1209,MATCH(D73&" | "&E73,Bang_gia!$A$2:$A$1209,0)),"")} | H73: =IF(OR(F73="",G73=""),"",F73*G73) | I73: =IF(D73="","",D73&" "&E73&IF(F73>1," x"&F73,"")) | J73: =IF(B73="","",B73&"|"&C73)
F74: 1 | G74: {=IFERROR(INDEX(Bang_gia!$E$2:$E$1209,MATCH(D74&" | "&E74,Bang_gia!$A$2:$A$1209,0)),"")} | H74: =IF(OR(F74="",G74=""),"",F74*G74) | I74: =IF(D74="","",D74&" "&E74&IF(F74>1," x"&F74,"")) | J74: =IF(B74="","",B74&"|"&C74)
F75: 1 | G75: {=IFERROR(INDEX(Bang_gia!$E$2:$E$1209,MATCH(D75&" | "&E75,Bang_gia!$A$2:$A$1209,0)),"")} | H75: =IF(OR(F75="",G75=""),"",F75*G75) | I75: =IF(D75="","",D75&" "&E75&IF(F75>1," x"&F75,"")) | J75: =IF(B75="","",B75&"|"&C75)
F76: 1 | G76: {=IFERROR(INDEX(Bang_gia!$E$2:$E$1209,MATCH(D76&" | "&E76,Bang_gia!$A$2:$A$1209,0)),"")} | H76: =IF(OR(F76="",G76=""),"",F76*G76) | I76: =IF(D76="","",D76&" "&E76&IF(F76>1," x"&F76,"")) | J76: =IF(B76="","",B76&"|"&C76)
F77: 1 | G77: {=IFERROR(INDEX(Bang_gia!$E$2:$E$1209,MATCH(D77&" | "&E77,Bang_gia!$A$2:$A$1209,0)),"")} | H77: =IF(OR(F77="",G77=""),"",F77*G77) | I77: =IF(D77="","",D77&" "&E77&IF(F77>1," x"&F77,"")) | J77: =IF(B77="","",B77&"|"&C77)
F78: 1 | G78: {=IFERROR(INDEX(Bang_gia!$E$2:$E$1209,MATCH(D78&" | "&E78,Bang_gia!$A$2:$A$1209,0)),"")} | H78: =IF(OR(F78="",G78=""),"",F78*G78) | I78: =IF(D78="","",D78&" "&E78&IF(F78>1," x"&F78,"")) | J78: =IF(B78="","",B78&"|"&C78)
... F1000: 1 | G1000: {=IFERROR(INDEX(Bang_gia!$E$2:$E$1209,MATCH(D1000&" | "&E1000,Bang_gia!$A$2:$A$1209,0)),"")} | H1000: =IF(OR(F1000="",G1000=""),"",F1000*G1000) | I1000: =IF(D1000="","",D1000&" "&E1000&IF(F1000>1," x"&F1000,"")) | J1000: =IF(B1000="","",B1000&"|"&C1000)

Sheet Khach_hang
A1: Tên KH (KHÔNG ĐƯỢC TRÙNG) | B1: SĐT | C1: Địa chỉ | D1: Ghi chú
A2: Anh Quân | F2: Thông tin khách hàng không cho phép trùng
A3: Chị Nga
A4: Bích Thuận
A5: Ms. Ngọc - Chung cư Feliz
A6: Mẹ Bột - Chung cư City Garden
A7: Yến Q7
A8: Trúc
A9: Huyền dạy yoga cổng vào Vista
A10: Anh Trung Vista
A11: Phụng Huỳnh | B11: 0785898050 | C11: Masteri Thảo Điền, Tháp T1,
A12: Bé Quỳnh
A13: Mai Thị Khuyên | B13: 0982877929 | C13: T4/22-03, chung cư Estella Heights, khu phố 9, phường Bình Trưng,
A14: Bích Trinh | B14: 038 772 9447 | C14: 675 nguyễn kiệm, phú nhuận
A15: Bé Huyền (Q2)
A16: Ms. Vân (Q1) | B16: 0907136100 | C16: Diamond Plaza, 34 Lê Duẩn phường Sài Gòn
A17: Chị Dung (A.Đức) | C17: 59 Vành Đai Tây
A18: Chị Oanh (Q11) | B18: 0918456744 | C18: 132 Ông Ích Khiêm, P5, Q11
A19: Chú Dụng | C19: Giao qua nhóm Bích
A20: Chị Thu (Phú Mỹ) | C20: Phú Mỹ VT
A21: Bé Huyền (An Phú Q2) | C21: An Phú
A22: Chị Xuân (Nhóm Bích) | C22: Nhóm Bích | D22: Giao 3h chiều Thứ 2, ngày 30/3
A23: Thương | C23: 214C/21 Lê Văn Thịnh
A24: Nguyễn Thanh Trúc (FB Thảo) | C24: Lấy tận nơi
A25: Bé Kiều (FIT) | C25: Giao qua nhóm fit
A26: Bé Hiền (khách FIT) | C26: Lấy tận nơi
A27: Chị Trần Lệ Ninh | B27: 0931863981 | C27: Cổng B cảng Cát Lái, số 2 Lê Phụng Hiểu, Q2
A28: Chị An Lạc (In Ấn) | B28: 0986994700 | C28: 32 - Đường 4B - Phường bình tân, TP. HCM
A29: Bích Trinh (VIB) 28.3 | C29: Lấy tận nơi
A30: Chị Oanh Auditor 28.3 | B30: 0936801123 | C30: 71/39/26A nguyễn bặc phường tân sơn hòa.
A31: Phạm Lê Thùy Ngân (Lâm Đồng) | B31: 0773815733 | C31: Ngân Thuỳ 0773815733 Nhà Thông Tàu - thôn 4, đinh trang thượng | D31: CN giao
A32: Chị Thi (Vietcombank) | B32: 0904453454 | C32: 303 Phan Đình Phùng, P.15, Phú Nhuận, | D32: Thứ 2 giao
A33: Trọng Dương | B33: FB page | C33: Lấy tận nơi 8h tối 1/4 | D33: đã giao
A34: Trần Thị Hải Yến | C34: Lấy tận nơi Vista Verde (CN hoặc T2)
A35: Minh Thị Võ | B35: FB page | C35: Lấy tận nơi Vista Verde (CN hoặc T2)
A36: Trịnh Châu | B36: 0984191939 | C36: 132/7 tân mỹ phường tân thuận tây q7 | D36: Giao Thứ 2
A37: Bích Nguyễn | C37: Nhóm Bích | D37: CN giao
A38: Chị Thanh (bạn Được | C38: Lấy tận nơi (hàng sẵn)
A39: Cha Ỉn | B39: 035 6653154 | C39: C15 cao thị chính phường Phú thuận quận 7 | D39: Giao Thứ 2
A40: Cam Tran | B40: 0913699168 | C40: Chung cư Q7, boulevard, 600 nguyễn lương bằng, lô A1, quận 7 | D40: Giao Thứ 2
...

Sheet Don_hang
A1: Mã đơn | B1: Ngày | C1: Tên KH | D1: Nhân viên Giới thiệu | E1: Địa chỉ | F1: SĐT | G1: Tổng SL | H1: Phí ship | I1: Shipper | J1: Tổng CHƯA SHIP | K1: Tổng CÓ SHIP | L1: Giảm giá 10% (%) | M1: Giảm giá (đ) | N1: Sau giảm (đ) | O1: Đã thanh toán | P1: TỔNG THANH TOÁN | Q1: Trạng thái đơn | R1: Trạng thái giao hàng | S1: Loại Đơn Hàng | T1: Ghi chú | V1: Cột vàng là để nhập: B, C, G, J, K
A2: DH0001 | B2: 46098 | C2: Anh Quân | D2: Thảo | E2: {=IF(C2="","",IFERROR(INDEX(Khach_hang!$C$2:$C$999,MATCH(C2,Khach_hang!$A$2:$A$999,0)),""))} | F2: {=IF(C2="","",IFERROR(INDEX(Khach_hang!$B$2:$B$999,MATCH(C2,Khach_hang!$A$2:$A$999,0)),""))} | G2: =IF(A2="","",SUMIF(Chi_tiet_don_hang!$A$2:$A$989,A2,Chi_tiet_don_hang!$F$2:$F$989)) -> 10 | H2: 0 | I2: - | J2: =K2-H2 -> 508000 | K2: =IF(A2="","",SUMIF(Chi_tiet_don_hang!$A$2:$A$989,A2,Chi_tiet_don_hang!$I$2:$I$989))+H2 -> 508000 | L2: 0.1 | M2: =(J2*L2) -> 50800 | N2: =J2-(J2*L2) -> 457200 | O2: 457200 | P2: =IF(A2="","",MAX(N2+H2-O2,0)) -> 0 | Q2: Đã thanh toán | R2: Đã giao hàng | S2: Hàng sẵn | V2: Lựa chọn ở cột: C
A3: DH0002 | B3: 46098 | C3: Chị Nga | D3: Hà | E3: 139/28 Phan đăng lưu, phường cầu kiệu. | F3: 0918757551 | G3: =IF(A3="","",SUMIF(Chi_tiet_don_hang!$A$2:$A$989,A3,Chi_tiet_don_hang!$F$2:$F$989)) -> 5 | H3: 40000 | I3: - | J3: =K3-H3 -> 396000 | K3: =IF(A3="","",SUMIF(Chi_tiet_don_hang!$A$2:$A$989,A3,Chi_tiet_don_hang!$I$2:$I$989))+H3 -> 436000 | L3: 0.1 | M3: =(J3*L3) -> 39600 | N3: =J3-(J3*L3) -> 356400 | O3: 396400 | P3: =IF(A3="","",MAX(N3+H3-O3,0)) -> 0 | Q3: Đã thanh toán | R3: Đã giao hàng | S3: Hàng sẵn | V3: Cột xám là tự tính, áp dụng công thức có sẵn từ những ô trên => Có thể copy xuống
A4: DH0003 | B4: 46098 | C4: Bích Thuận | D4: Thảo | E4: {=IF(C4="","",IFERROR(INDEX(Khach_hang!$C$2:$C$999,MATCH(C4,Khach_hang!$A$2:$A$999,0)),""))} | F4: {=IF(C4="","",IFERROR(INDEX(Khach_hang!$B$2:$B$999,MATCH(C4,Khach_hang!$A$2:$A$999,0)),""))} | G4: =IF(A4="","",SUMIF(Chi_tiet_don_hang!$A$2:$A$989,A4,Chi_tiet_don_hang!$F$2:$F$989)) -> 5 | H4: 0 | I4: - | J4: =K4-H4 -> 202000 | K4: =IF(A4="","",SUMIF(Chi_tiet_don_hang!$A$2:$A$989,A4,Chi_tiet_don_hang!$I$2:$I$989))+H4 -> 202000 | L4: 0.1 | M4: =(J4*L4) -> 20200 | N4: =J4-(J4*L4) -> 181800 | O4: 181800 | P4: =IF(A4="","",MAX(N4+H4-O4,0)) -> 0 | Q4: Đã thanh toán | R4: Đã giao hàng | S4: Hàng sẵn
A5: DH0004 | B5: 46098 | C5: Ms. Ngọc - Chung cư Feliz | D5: Hằng | E5: {=IF(C5="","",IFERROR(INDEX(Khach_hang!$C$2:$C$999,MATCH(C5,Khach_hang!$A$2:$A$999,0)),""))} | F5: {=IF(C5="","",IFERROR(INDEX(Khach_hang!$B$2:$B$999,MATCH(C5,Khach_hang!$A$2:$A$999,0)),""))} | G5: =IF(A5="","",SUMIF(Chi_tiet_don_hang!$A$2:$A$989,A5,Chi_tiet_don_hang!$F$2:$F$989)) -> 5 | H5: 0 | I5: - | J5: =K5-H5 -> 372000 | K5: =IF(A5="","",SUMIF(Chi_tiet_don_hang!$A$2:$A$989,A5,Chi_tiet_don_hang!$I$2:$I$989))+H5 -> 372000 | L5: 0.1 | M5: =(J5*L5) -> 37200 | N5: =J5-(J5*L5) -> 334800 | O5: 332000 | P5: =IF(A5="","",MAX(N5+H5-O5,0)) -> 2800 | Q5: Đã thanh toán | R5: Đã giao hàng | S5: Hàng sẵn
A6: DH0005 | B6: 46098 | C6: Mẹ Bột - Chung cư City Garden | D6: Thảo | E6: Chung cư city garden Tháp 1 (59 ngô tất tố) | F6: 077 2017375 | G6: =IF(A6="","",SUMIF(Chi_tiet_don_hang!$A$2:$A$989,A6,Chi_tiet_don_hang!$F$2:$F$989)) -> 5 | H6: 30000 | I6: - | J6: =K6-H6 -> 260000 | K6: =IF(A6="","",SUMIF(Chi_tiet_don_hang!$A$2:$A$989,A6,Chi_tiet_don_hang!$I$2:$I$989))+H6 -> 290000 | L6: 0.1 | M6: =(J6*L6) -> 26000 | N6: =J6-(J6*L6) -> 234000 | O6: 264000 | P6: =IF(A6="","",MAX(N6+H6-O6,0)) -> 0 | Q6: Đã thanh toán | R6: Đã giao hàng | S6: Hàng sẵn
A7: DH0006 | B7: 46098 | C7: Yến Q7 | D7: Hằng | E7: {=IF(C7="","",IFERROR(INDEX(Khach_hang!$C$2:$C$999,MATCH(C7,Khach_hang!$A$2:$A$999,0)),""))} | F7: {=IF(C7="","",IFERROR(INDEX(Khach_hang!$B$2:$B$999,MATCH(C7,Khach_hang!$A$2:$A$999,0)),""))} | G7: =IF(A7="","",SUMIF(Chi_tiet_don_hang!$A$2:$A$989,A7,Chi_tiet_don_hang!$F$2:$F$989)) -> 13 | H7: 55000 | I7: - | J7: =K7-H7 -> 701000 | K7: =IF(A7="","",SUMIF(Chi_tiet_don_hang!$A$2:$A$989,A7,Chi_tiet_don_hang!$I$2:$I$989))+H7 -> 756000 | L7: 0.1 | M7: =(J7*L7) -> 70100 | N7: =J7-(J7*L7) -> 630900 | O7: 685900 | P7: =IF(A7="","",MAX(N7+H7-O7,0)) -> 0 | Q7: Đã thanh toán | R7: Đã giao hàng | S7: Hàng sẵn
A8: DH0007 | B8: 46098 | C8: Trúc | D8: Hằng | E8: {=IF(C8="","",IFERROR(INDEX(Khach_hang!$C$2:$C$999,MATCH(C8,Khach_hang!$A$2:$A$999,0)),""))} | F8: {=IF(C8="","",IFERROR(INDEX(Khach_hang!$B$2:$B$999,MATCH(C8,Khach_hang!$A$2:$A$999,0)),""))} | G8: =IF(A8="","",SUMIF(Chi_tiet_don_hang!$A$2:$A$989,A8,Chi_tiet_don_hang!$F$2:$F$989)) -> 5 | H8: 0 | I8: - | J8: =K8-H8 -> 186000 | K8: =IF(A8="","",SUMIF(Chi_tiet_don_hang!$A$2:$A$989,A8,Chi_tiet_don_hang!$I$2:$I$989))+H8 -> 186000 | L8: 0.1 | M8: =(J8*L8) -> 18600 | N8: =J8-(J8*L8) -> 167400 | O8: 168000 | P8: =IF(A8="","",MAX(N8+H8-O8,0)) -> 0 | Q8: Đã thanh toán | R8: Đã giao hàng | S8: Hàng sẵn
A9: DH0008 | B9: 46098 | C9: Huyền dạy yoga cổng vào Vista | D9: Hà | E9: {=IF(C9="","",IFERROR(INDEX(Khach_hang!$C$2:$C$999,MATCH(C9,Khach_hang!$A$2:$A$999,0)),""))} | F9: {=IF(C9="","",IFERROR(INDEX(Khach_hang!$B$2:$B$999,MATCH(C9,Khach_hang!$A$2:$A$999,0)),""))} | G9: =IF(A9="","",SUMIF(Chi_tiet_don_hang!$A$2:$A$989,A9,Chi_tiet_don_hang!$F$2:$F$989)) -> 2 | H9: 0 | I9: - | J9: =K9-H9 -> 72000 | K9: =IF(A9="","",SUMIF(Chi_tiet_don_hang!$A$2:$A$989,A9,Chi_tiet_don_hang!$I$2:$I$989))+H9 -> 72000 | L9: 0.1 | M9: =(J9*L9) -> 7200 | N9: =J9-(J9*L9) -> 64800 | O9: 64800 | P9: =IF(A9="","",MAX(N9+H9-O9,0)) -> 0 | Q9: Đã thanh toán | R9: Đã giao hàng | S9: Hàng sẵn
A10: DH0009 | B10: 46099 | C10: Anh Trung Vista | D10: Hà | E10: {=IF(C10="","",IFERROR(INDEX(Khach_hang!$C$2:$C$999,MATCH(C10,Khach_hang!$A$2:$A$999,0)),""))} | F10: {=IF(C10="","",IFERROR(INDEX(Khach_hang!$B$2:$B$999,MATCH(C10,Khach_hang!$A$2:$A$999,0)),""))} | G10: =IF(A10="","",SUMIF(Chi_tiet_don_hang!$A$2:$A$989,A10,Chi_tiet_don_hang!$F$2:$F$989)) -> 5 | H10: 0 | I10: - | J10: =K10-H10 -> 260000 | K10: =IF(A10="","",SUMIF(Chi_tiet_don_hang!$A$2:$A$989,A10,Chi_tiet_don_hang!$I$2:$I$989))+H10 -> 260000 | L10: 0.1 | M10: =(J10*L10) -> 26000 | N10: =J10-(J10*L10) -> 234000 | O10: 234000 | P10: =IF(A10="","",MAX(N10+H10-O10,0)) -> 0 | Q10: Đã thanh toán | R10: Đã giao hàng | S10: Hàng sẵn
A11: DH0010 | B11: 46100 | C11: Phụng Huỳnh | D11: Hà | E11: {=IF(C11="","",IFERROR(INDEX(Khach_hang!$C$2:$C$999,MATCH(C11,Khach_hang!$A$2:$A$999,0)),""))} -> Masteri Thảo Điền, Tháp T1, | F11: {=IF(C11="","",IFERROR(INDEX(Khach_hang!$B$2:$B$999,MATCH(C11,Khach_hang!$A$2:$A$999,0)),""))} -> 0785898050 | G11: =IF(A11="","",SUMIF(Chi_tiet_don_hang!$A$2:$A$989,A11,Chi_tiet_don_hang!$F$2:$F$989)) -> 5 | H11: 35000 | I11: - | J11: =K11-H11 -> 215000 | K11: =IF(A11="","",SUMIF(Chi_tiet_don_hang!$A$2:$A$989,A11,Chi_tiet_don_hang!$I$2:$I$989))+H11 -> 250000 | L11: 0.1 | M11: =(J11*L11) -> 21500 | N11: =J11-(J11*L11) -> 193500 | O11: 228500 | P11: =IF(A11="","",MAX(N11+H11-O11,0)) -> 0 | Q11: Đã thanh toán | R11: Đã giao hàng | S11: Hàng sẵn
A12: DH0011 | B12: 46100 | C12: Bé Quỳnh | D12: Uyên | E12: {=IF(C12="","",IFERROR(INDEX(Khach_hang!$C$2:$C$999,MATCH(C12,Khach_hang!$A$2:$A$999,0)),""))} | F12: {=IF(C12="","",IFERROR(INDEX(Khach_hang!$B$2:$B$999,MATCH(C12,Khach_hang!$A$2:$A$999,0)),""))} | G12: =IF(A12="","",SUMIF(Chi_tiet_don_hang!$A$2:$A$989,A12,Chi_tiet_don_hang!$F$2:$F$989)) -> 3 | H12: 0 | I12: - | J12: =K12-H12 -> 108000 | K12: =IF(A12="","",SUMIF(Chi_tiet_don_hang!$A$2:$A$989,A12,Chi_tiet_don_hang!$I$2:$I$989))+H12 -> 108000 | L12: 0.1 | M12: =(J12*L12) -> 10800 | N12: =J12-(J12*L12) -> 97200 | O12: 97200 | P12: =IF(A12="","",MAX(N12+H12-O12,0)) -> 0 | Q12: Đã thanh toán | R12: Đã giao hàng | S12: Hàng sẵn
A13: DH0012 | B13: 20/03/2026 | C13: Mai Thị Khuyên | D13: Hà | E13: {=IF(C13="","",IFERROR(INDEX(Khach_hang!$C$2:$C$999,MATCH(C13,Khach_hang!$A$2:$A$999,0)),""))} -> T4/22-03, chung cư Estella Heights, khu phố 9, phường Bình Trưng, | F13: {=IF(C13="","",IFERROR(INDEX(Khach_hang!$B$2:$B$999,MATCH(C13,Khach_hang!$A$2:$A$999,0)),""))} -> 0982877929 | G13: =IF(A13="","",SUMIF(Chi_tiet_don_hang!$A$2:$A$989,A13,Chi_tiet_don_hang!$F$2:$F$989)) -> 5 | H13: 35000 | I13: - | J13: =K13-H13 -> 281000 | K13: =IF(A13="","",SUMIF(Chi_tiet_don_hang!$A$2:$A$989,A13,Chi_tiet_don_hang!$I$2:$I$989))+H13 -> 316000 | L13: 0.1 | M13: =(J13*L13) -> 28100 | N13: =J13-(J13*L13) -> 252900 | O13: 288000 | P13: =IF(A13="","",MAX(N13+H13-O13,0)) -> 0 | Q13: Đã thanh toán | R13: Đã giao hàng | S13: Hàng sẵn | T13: Trả ship anh kềnh 140k
A14: DH0013 | B14: 21/03/2026 | C14: Bích Trinh | D14: Hằng | E14: {=IF(C14="","",IFERROR(INDEX(Khach_hang!$C$2:$C$999,MATCH(C14,Khach_hang!$A$2:$A$999,0)),""))} -> 675 nguyễn kiệm, phú nhuận | F14: {=IF(C14="","",IFERROR(INDEX(Khach_hang!$B$2:$B$999,MATCH(C14,Khach_hang!$A$2:$A$999,0)),""))} -> 038 772 9447 | G14: =IF(A14="","",SUMIF(Chi_tiet_don_hang!$A$2:$A$989,A14,Chi_tiet_don_hang!$F$2:$F$989)) -> 5 | H14: 60000 | I14: - | J14: =K14-H14 -> 308500 | K14: =IF(A14="","",SUMIF(Chi_tiet_don_hang!$A$2:$A$989,A14,Chi_tiet_don_hang!$I$2:$I$989))+H14 -> 368500 | L14: 0.1 | M14: =(J14*L14) -> 30850 | N14: =J14-(J14*L14) -> 277650 | O14: 337650 | P14: =IF(A14="","",MAX(N14+H14-O14,0)) -> 0 | Q14: Đã thanh toán | R14: Đã giao hàng | S14: Hàng sẵn
A15: DH0014 | B15: 21/03/2026 | C15: Bé Huyền (Q2) | D15: Hằng | E15: Tới Vista lấy | F15: {=IF(C15="","",IFERROR(INDEX(Khach_hang!$B$2:$B$999,MATCH(C15,Khach_hang!$A$2:$A$999,0)),""))} | G15: =IF(A15="","",SUMIF(Chi_tiet_don_hang!$A$2:$A$989,A15,Chi_tiet_don_hang!$F$2:$F$989)) -> 4 | H15: 0 | I15: - | J15: =K15-H15 -> 115500 | K15: =IF(A15="","",SUMIF(Chi_tiet_don_hang!$A$2:$A$989,A15,Chi_tiet_don_hang!$I$2:$I$989))+H15 -> 115500 | L15: 0.1 | M15: =(J15*L15) -> 11550 | N15: =J15-(J15*L15) -> 103950 | O15: 104000 | P15: =IF(A15="","",MAX(N15+H15-O15,0)) -> 0 | Q15: Đã thanh toán | R15: Đã giao hàng | S15: Hàng sẵn
A16: DH0015 | B16: 23/03/2026 | C16: Ms. Vân (Q1) | D16: Hằng | E16: {=IF(C16="","",IFERROR(INDEX(Khach_hang!$C$2:$C$999,MATCH(C16,Khach_hang!$A$2:$A$999,0)),""))} -> Diamond Plaza, 34 Lê Duẩn phường Sài Gòn | F16: {=IF(C16="","",IFERROR(INDEX(Khach_hang!$B$2:$B$999,MATCH(C16,Khach_hang!$A$2:$A$999,0)),""))} -> 0907136100 | G16: =IF(A16="","",SUMIF(Chi_tiet_don_hang!$A$2:$A$989,A16,Chi_tiet_don_hang!$F$2:$F$989)) -> 6 | H16: 0 | I16: - | J16: =K16-H16 -> 285100 | K16: =IF(A16="","",SUMIF(Chi_tiet_don_hang!$A$2:$A$989,A16,Chi_tiet_don_hang!$I$2:$I$989))+H16 -> 285100 | L16: 0.1 | M16: =(J16*L16) -> 28510 | N16: =J16-(J16*L16) -> 256590 | O16: 256590 | P16: =IF(A16="","",MAX(N16+H16-O16,0)) -> 0 | Q16: Đã thanh toán | R16: Đã giao hàng | S16: Hàng sẵn
A17: DH0016 | B17: 22/03/2026 | C17: Chị Dung (A.Đức) | D17: Hằng | E17: {=IF(C17="","",IFERROR(INDEX(Khach_hang!$C$2:$C$999,MATCH(C17,Khach_hang!$A$2:$A$999,0)),""))} -> 59 Vành Đai Tây | F17: {=IF(C17="","",IFERROR(INDEX(Khach_hang!$B$2:$B$999,MATCH(C17,Khach_hang!$A$2:$A$999,0)),""))} | G17: =IF(A17="","",SUMIF(Chi_tiet_don_hang!$A$2:$A$989,A17,Chi_tiet_don_hang!$F$2:$F$989)) -> 5 | H17: 25000 | I17: - | J17: =K17-H17 -> 394000 | K17: =IF(A17="","",SUMIF(Chi_tiet_don_hang!$A$2:$A$989,A17,Chi_tiet_don_hang!$I$2:$I$989))+H17 -> 419000 | L17: 0.1 | M17: =(J17*L17) -> 39400 | N17: =J17-(J17*L17) -> 354600 | O17: 380000 | P17: =IF(A17="","",MAX(N17+H17-O17,0)) -> 0 | Q17: Đã thanh toán | R17: Đã giao hàng | S17: Hàng sẵn
A18: DH0017 | B18: 23/03/2026 | C18: Chị Oanh (Q11) | D18: Hằng | E18: {=IF(C18="","",IFERROR(INDEX(Khach_hang!$C$2:$C$999,MATCH(C18,Khach_hang!$A$2:$A$999,0)),""))} -> 132 Ông Ích Khiêm, P5, Q11 | F18: {=IF(C18="","",IFERROR(INDEX(Khach_hang!$B$2:$B$999,MATCH(C18,Khach_hang!$A$2:$A$999,0)),""))} -> 0918456744 | G18: =IF(A18="","",SUMIF(Chi_tiet_don_hang!$A$2:$A$989,A18,Chi_tiet_don_hang!$F$2:$F$989)) -> 12 | H18: 70000 | I18: - | J18: =K18-H18 -> 886000 | K18: =IF(A18="","",SUMIF(Chi_tiet_don_hang!$A$2:$A$989,A18,Chi_tiet_don_hang!$I$2:$I$989))+H18 -> 956000 | L18: 0.1 | M18: =(J18*L18) -> 88600 | N18: =J18-(J18*L18) -> 797400 | O18: 870000 | P18: =IF(A18="","",MAX(N18+H18-O18,0)) -> 0 | Q18: Đã thanh toán | R18: Đã giao hàng | S18: Hàng sẵn
A19: DH0018 | B19: 24/03/2026 | C19: Chú Dụng | D19: Hằng | E19: {=IF(C19="","",IFERROR(INDEX(Khach_hang!$C$2:$C$999,MATCH(C19,Khach_hang!$A$2:$A$999,0)),""))} -> Giao qua nhóm Bích | F19: {=IF(C19="","",IFERROR(INDEX(Khach_hang!$B$2:$B$999,MATCH(C19,Khach_hang!$A$2:$A$999,0)),""))} | G19: =IF(A19="","",SUMIF(Chi_tiet_don_hang!$A$2:$A$989,A19,Chi_tiet_don_hang!$F$2:$F$989)) -> 5 | H19: 0 | I19: - | J19: =K19-H19 -> 190750 | K19: =IF(A19="","",SUMIF(Chi_tiet_don_hang!$A$2:$A$989,A19,Chi_tiet_don_hang!$I$2:$I$989))+H19 -> 190750 | L19: 0.1 | M19: =(J19*L19) -> 19075 | N19: =J19-(J19*L19) -> 171675 | O19: 172000 | P19: =IF(A19="","",MAX(N19+H19-O19,0)) -> 0 | Q19: Đã thanh toán | R19: Đã giao hàng | S19: Hàng sẵn
